Loading tensorflow2-py37-cuda10.2-gcc/2.2.0
  Loading requirement: openblas/dynamic/0.3.7 hdf5_18/1.8.21 gcc5/5.5.0 python37
    cuda10.2/toolkit/10.2.89 cudnn7.6-cuda10.2/7.6.5.32
    ml-pythondeps-py37-cuda10.2-gcc/4.3.9 protobuf3-gcc/3.8.0
    nccl2-cuda10.2-gcc/2.7.8
CPUs allocated: hpc-gn004.cm.cluster
This PBS script is running on host hpc-gn004
Working directory is /home/d24h_prog2/pypy/ARG_MGE_platform/ARGNet/scripts
2023-03-10 18:32:47.552003: I tensorflow/stream_executor/platform/default/dso_loader.cc:44] Successfully opened dynamic library libcudart.so.10.2
Traceback (most recent call last):
  File "/home/d24h_prog2/pypy/ARG_MGE_platform/ARGNet/scripts/argnet.py", line 55, in <module>
    import  argnet_ssnt_new as ssnt
  File "/home/d24h_prog2/pypy/ARG_MGE_platform/ARGNet/scripts/argnet_ssnt_new.py", line 34, in <module>
    filterm = tf.keras.models.load_model(os.path.join(os.path.dirname(__file__), '../model/AESS_tall.h5'))
  File "/cm/shared/apps/tensorflow2-py37-cuda10.2-gcc/2.2.0/lib/python3.7/site-packages/tensorflow/python/keras/saving/save.py", line 189, in load_model
    loader_impl.parse_saved_model(filepath)
  File "/cm/shared/apps/tensorflow2-py37-cuda10.2-gcc/2.2.0/lib/python3.7/site-packages/tensorflow/python/saved_model/loader_impl.py", line 113, in parse_saved_model
    constants.SAVED_MODEL_FILENAME_PB))
OSError: SavedModel file does not exist at: /home/d24h_prog2/pypy/ARG_MGE_platform/ARGNet/scripts/../model/AESS_tall.h5/{saved_model.pbtxt|saved_model.pb}
